
# Created by Ruins mod version 14.6 Ingame Parser
# authoring Player: Khirgil

weight=1
embed_into_distance=0
acceptable_target_blocks=
unacceptable_target_blocks=flowing_water,water,flowing_lava,lava
dimensions=19,27,27
allowable_overhang=0
max_leveling=2
leveling_buffer=0
preserve_water=0
preserve_lava=0

rule1=0,100,Railcraft:brick.bleachedbone-1
rule2=0,100,TConstruct:liquid.blood-1
rule3=0,100,Railcraft:brick.bleachedbone-0
rule4=0,100,TConstruct:liquid.blood-2
rule5=0,100,TConstruct:liquid.blood-3
rule6=0,100,Railcraft:wall.beta-8
rule7=0,100,GraveStone:GSPileOfBones-1
rule8=0,100,GraveStone:GSPileOfBones-0
rule9=0,100,Railcraft:stair-2
rule10=0,100,Railcraft:stair-0
rule11=0,100,Railcraft:stair-3
rule12=0,100,Railcraft:brick.bleachedbone-2
rule13=0,100,Railcraft:brick.bloodstained-0
rule14=0,100,IInventory;BiblioCraft:BiblioTable;minecraft:carpet#1#14#1-6
rule15=0,100,BiblioCraft:BiblioDesk-6
rule16=0,100,IInventory;BiblioCraft:BiblioTable;GraveStone:GSPileOfBones#1#1#0+minecraft:carpet#1#15#1-6
rule17=0,100,IInventory;BiblioCraft:BiblioSeats;minecraft:carpet#1#15#0+BiblioCraft:item.seatBack5#1#6#1-6
rule18=0,100,IInventory;BiblioCraft:BiblioDesk;minecraft:writable_book#1#0#0+minecraft:writable_book#1#0#1-6
rule19=0,100,Railcraft:stair-1
rule20=0,100,GraveStone:GSSkullCandle-0
rule21=0,100,Railcraft:slab-0
rule22=0,100,Railcraft:stair-7
rule23=0,100,GraveStone:GSSpawner-1
rule24=0,100,Railcraft:wall.beta-7
rule25=0,100,Railcraft:stair-6
rule26=0,100,Railcraft:stair-4
rule27=0,100,TConstruct:liquid.blood-0
rule28=0,100,Railcraft:stair-5

layer
0,0,0,0,0,0,0,0,0,0,0,0,0,0,0,0,0,0,0,0,0,0,0,0,0,0,0
0,0,0,0,0,0,0,0,0,0,0,0,0,0,0,0,0,0,0,0,0,0,0,0,0,0,0
0,0,0,0,0,0,0,0,0,0,1,1,1,1,1,1,1,0,0,0,0,0,0,0,0,0,0
0,0,0,0,0,0,0,0,0,1,1,1,1,1,1,1,1,1,0,0,0,0,0,0,0,0,0
0,0,0,0,0,0,0,0,1,1,1,1,1,1,1,1,1,1,1,0,0,0,0,0,0,0,0
0,0,0,0,0,0,0,1,1,1,1,1,1,1,1,1,1,1,1,1,0,0,0,0,0,0,0
0,0,0,0,0,0,1,1,1,1,1,1,1,1,1,1,1,1,1,1,1,0,0,0,0,0,0
0,0,0,0,0,1,1,1,1,1,1,1,2,2,2,1,1,1,1,1,1,1,0,0,0,0,0
0,0,0,0,1,1,1,1,1,1,1,1,2,2,2,1,1,1,1,1,1,1,1,0,0,0,0
0,0,0,1,1,1,1,1,1,3,3,3,4,4,4,3,3,3,1,1,1,1,1,1,0,0,0
0,0,0,1,1,1,1,1,1,3,3,3,5,5,5,3,3,3,1,1,1,1,1,1,1,0,0
0,0,0,1,1,1,1,1,1,3,3,1,1,1,1,1,3,3,1,1,1,1,1,1,1,0,0
0,0,0,1,1,1,1,1,1,3,3,1,1,1,1,1,3,3,1,1,1,1,1,1,1,0,0
0,0,0,1,1,1,1,1,1,3,3,1,1,1,1,1,3,3,1,1,1,1,1,1,1,0,0
0,0,0,1,1,1,1,1,1,3,3,1,1,1,1,1,3,3,1,1,1,1,1,1,1,0,0
0,0,0,1,1,1,1,1,1,3,3,1,1,1,1,1,3,3,1,1,1,1,1,1,1,0,0
0,0,0,1,1,1,1,1,1,3,3,3,5,5,5,3,3,3,1,1,1,1,1,1,1,0,0
0,0,0,1,1,1,1,1,1,3,3,3,4,4,4,3,3,3,1,1,1,1,1,1,0,0,0
0,0,0,0,1,1,1,1,1,1,1,1,2,2,2,1,1,1,1,1,1,1,1,0,0,0,0
0,0,0,0,0,1,1,1,1,1,1,1,2,2,2,1,1,1,1,1,1,1,0,0,0,0,0
0,0,0,0,0,0,1,1,1,1,1,1,1,1,1,1,1,1,1,1,1,0,0,0,0,0,0
0,0,0,0,0,0,0,1,1,1,1,1,1,1,1,1,1,1,1,1,0,0,0,0,0,0,0
0,0,0,0,0,0,0,0,1,1,1,1,1,1,1,1,1,1,1,0,0,0,0,0,0,0,0
0,0,0,0,0,0,0,0,0,1,1,1,1,1,1,1,1,1,0,0,0,0,0,0,0,0,0
0,0,0,0,0,0,0,0,0,0,1,1,1,1,1,1,1,0,0,0,0,0,0,0,0,0,0
0,0,0,0,0,0,0,0,0,0,0,0,0,0,0,0,0,0,0,0,0,0,0,0,0,0,0
0,0,0,0,0,0,0,0,0,0,0,0,0,0,0,0,0,0,0,0,0,0,0,0,0,0,0
endlayer

layer
0,0,0,0,0,0,0,0,0,0,0,0,0,0,0,0,0,0,0,0,0,0,0,0,0,0,0
0,0,0,0,0,0,0,0,0,0,0,0,0,0,0,0,0,0,0,0,0,0,0,0,0,0,0
0,0,0,0,0,0,0,0,0,1,1,0,0,0,0,0,1,1,0,0,0,0,0,0,0,0,0
0,0,0,0,0,0,0,0,1,0,0,0,0,0,0,0,0,0,1,0,0,0,0,0,0,0,0
0,0,0,0,0,0,0,1,0,0,0,0,0,0,0,0,0,0,0,1,0,0,0,0,0,0,0
0,0,0,0,0,0,1,0,0,0,0,0,0,0,0,0,0,0,0,0,1,0,0,0,0,0,0
0,0,0,0,0,1,0,0,0,0,0,0,0,6,0,0,0,0,0,0,0,1,0,0,0,0,0
0,0,0,0,1,0,0,0,0,0,0,6,2,2,2,6,0,0,0,0,0,0,1,0,0,0,0
0,0,0,1,0,0,0,0,1,1,0,0,0,0,0,0,0,1,1,0,0,0,0,1,0,0,0
0,0,1,0,0,0,0,0,1,7,8,0,0,0,0,0,8,7,1,0,0,0,0,0,1,0,0
0,0,1,0,0,0,0,0,0,8,0,11,10,10,10,9,0,8,0,0,0,0,0,0,1,0,0
0,0,1,0,0,0,0,0,0,0,0,1,12,12,12,10,10,0,0,0,0,0,0,0,0,0,0
0,0,1,15,0,0,0,0,0,14,0,12,13,13,13,12,9,0,0,0,0,0,0,0,0,0,0
0,0,1,18,17,0,0,0,0,16,0,12,13,13,13,12,9,0,0,0,0,0,0,0,0,0,0
0,0,1,15,0,0,0,0,0,14,0,12,13,13,13,12,9,0,0,0,0,0,0,0,0,0,0
0,0,1,0,0,0,0,0,0,0,0,1,12,12,12,19,19,0,0,0,0,0,0,0,0,0,0
0,0,1,0,0,0,0,0,0,8,0,11,19,19,19,9,0,8,0,0,0,0,0,0,1,0,0
0,0,1,0,0,0,0,0,1,7,8,0,0,0,0,0,8,7,1,0,0,0,0,0,1,0,0
0,0,0,1,0,0,0,0,1,1,0,0,0,0,0,0,0,1,1,0,0,0,0,1,0,0,0
0,0,0,0,1,0,0,0,0,0,0,6,2,2,2,6,0,0,0,0,0,0,1,0,0,0,0
0,0,0,0,0,1,0,0,0,0,0,0,0,6,0,0,0,0,0,0,0,1,0,0,0,0,0
0,0,0,0,0,0,1,0,0,0,0,0,0,0,0,0,0,0,0,0,1,0,0,0,0,0,0
0,0,0,0,0,0,0,1,0,0,0,0,0,0,0,0,0,0,0,1,0,0,0,0,0,0,0
0,0,0,0,0,0,0,0,1,0,0,0,0,0,0,0,0,0,1,0,0,0,0,0,0,0,0
0,0,0,0,0,0,0,0,0,1,1,0,0,0,0,0,1,1,0,0,0,0,0,0,0,0,0
0,0,0,0,0,0,0,0,0,0,0,0,0,0,0,0,0,0,0,0,0,0,0,0,0,0,0
0,0,0,0,0,0,0,0,0,0,0,0,0,0,0,0,0,0,0,0,0,0,0,0,0,0,0
endlayer

layer
0,0,0,0,0,0,0,0,0,0,0,0,0,0,0,0,0,0,0,0,0,0,0,0,0,0,0
0,0,0,0,0,0,0,0,0,0,0,0,0,0,0,0,0,0,0,0,0,0,0,0,0,0,0
0,0,0,0,0,0,0,0,0,1,1,0,0,0,0,0,1,1,0,0,0,0,0,0,0,0,0
0,0,0,0,0,0,0,0,1,0,0,0,0,0,0,0,0,0,1,0,0,0,0,0,0,0,0
0,0,0,0,0,0,0,1,0,0,0,0,0,0,0,0,0,0,0,1,0,0,0,0,0,0,0
0,0,0,0,0,0,1,0,0,0,0,0,0,0,0,0,0,0,0,0,1,0,0,0,0,0,0
0,0,0,0,0,1,0,0,0,0,0,0,0,6,0,0,0,0,0,0,0,1,0,0,0,0,0
0,0,0,0,1,0,0,0,0,0,0,6,2,2,2,6,0,0,0,0,0,0,1,0,0,0,0
0,0,0,1,0,0,0,0,6,20,0,0,0,0,0,0,0,20,6,0,0,0,0,1,0,0,0
0,0,1,0,0,0,0,0,20,0,0,0,0,0,0,0,0,0,20,0,0,0,0,0,1,0,0
0,0,1,0,0,0,0,0,0,0,0,0,0,0,0,0,0,0,0,0,0,0,0,0,1,0,0
0,0,1,0,0,0,0,0,0,0,21,1,7,8,8,0,0,0,0,0,0,0,0,0,0,0,0
0,0,1,0,0,0,0,0,0,20,22,9,0,0,8,8,0,0,0,0,0,0,0,0,0,0,0
0,0,1,0,0,0,0,0,0,8,22,9,0,23,0,8,0,0,0,0,0,0,0,0,0,0,0
0,0,1,0,0,0,0,0,0,20,22,9,0,0,8,0,0,0,0,0,0,0,0,0,0,0,0
0,0,1,0,0,0,0,0,0,0,21,1,7,8,8,0,0,0,0,0,0,0,0,0,0,0,0
0,0,1,0,0,0,0,0,0,0,0,0,0,0,0,0,0,0,0,0,0,0,0,0,1,0,0
0,0,1,0,0,0,0,0,20,0,0,0,0,0,0,0,0,0,20,0,0,0,0,0,1,0,0
0,0,0,1,0,0,0,0,6,20,0,0,0,0,0,0,0,20,6,0,0,0,0,1,0,0,0
0,0,0,0,1,0,0,0,0,0,0,6,2,2,2,6,0,0,0,0,0,0,1,0,0,0,0
0,0,0,0,0,1,0,0,0,0,0,0,0,6,0,0,0,0,0,0,0,1,0,0,0,0,0
0,0,0,0,0,0,1,0,0,0,0,0,0,0,0,0,0,0,0,0,1,0,0,0,0,0,0
0,0,0,0,0,0,0,1,0,0,0,0,0,0,0,0,0,0,0,1,0,0,0,0,0,0,0
0,0,0,0,0,0,0,0,1,0,0,0,0,0,0,0,0,0,1,0,0,0,0,0,0,0,0
0,0,0,0,0,0,0,0,0,1,1,0,0,0,0,0,1,1,0,0,0,0,0,0,0,0,0
0,0,0,0,0,0,0,0,0,0,0,0,0,0,0,0,0,0,0,0,0,0,0,0,0,0,0
0,0,0,0,0,0,0,0,0,0,0,0,0,0,0,0,0,0,0,0,0,0,0,0,0,0,0
endlayer

layer
0,0,0,0,0,0,0,0,0,0,0,0,0,0,0,0,0,0,0,0,0,0,0,0,0,0,0
0,0,0,0,0,0,0,0,0,0,0,0,0,0,0,0,0,0,0,0,0,0,0,0,0,0,0
0,0,0,0,0,0,0,0,0,1,1,21,0,0,0,21,1,1,0,0,0,0,0,0,0,0,0
0,0,0,0,0,0,0,0,1,0,0,0,0,0,0,0,0,0,1,0,0,0,0,0,0,0,0
0,0,0,0,0,0,0,1,0,0,0,0,0,0,0,0,0,0,0,1,0,0,0,0,0,0,0
0,0,0,0,0,0,1,0,0,0,0,0,0,0,0,0,0,0,0,0,1,0,0,0,0,0,0
0,0,0,0,0,1,0,0,0,0,0,0,6,6,6,0,0,0,0,0,0,1,0,0,0,0,0
0,0,0,0,1,0,0,0,0,0,0,6,2,2,2,6,0,0,0,0,0,0,1,0,0,0,0
0,0,0,1,0,0,0,0,6,0,0,0,0,0,0,0,0,0,6,0,0,0,0,1,0,0,0
0,0,1,0,0,0,0,0,0,0,0,0,0,0,0,0,0,0,0,0,0,0,0,0,1,0,0
0,0,1,0,0,0,0,0,0,0,0,0,0,0,0,0,0,0,0,0,0,0,0,0,1,0,0
0,0,1,0,0,0,0,0,0,21,1,1,0,0,0,0,0,0,0,0,0,0,0,0,21,0,0
0,0,1,0,0,0,0,0,0,22,9,0,0,0,0,0,0,0,0,0,0,0,0,0,0,0,0
0,0,1,0,0,0,0,0,0,22,9,0,0,0,0,0,0,0,0,0,0,0,0,0,0,0,0
0,0,1,0,0,0,0,0,0,22,9,0,0,0,0,0,0,0,0,0,0,0,0,0,0,0,0
0,0,1,0,0,0,0,0,0,21,1,1,0,0,0,0,0,0,0,0,0,0,0,0,21,0,0
0,0,1,0,0,0,0,0,0,0,0,0,0,0,0,0,0,0,0,0,0,0,0,0,1,0,0
0,0,1,0,0,0,0,0,0,0,0,0,0,0,0,0,0,0,0,0,0,0,0,0,1,0,0
0,0,0,1,0,0,0,0,6,0,0,0,0,0,0,0,0,0,6,0,0,0,0,1,0,0,0
0,0,0,0,1,0,0,0,0,0,0,6,2,2,2,6,0,0,0,0,0,0,1,0,0,0,0
0,0,0,0,0,1,0,0,0,0,0,0,6,6,6,0,0,0,0,0,0,1,0,0,0,0,0
0,0,0,0,0,0,1,0,0,0,0,0,0,0,0,0,0,0,0,0,1,0,0,0,0,0,0
0,0,0,0,0,0,0,1,0,0,0,0,0,0,0,0,0,0,0,1,0,0,0,0,0,0,0
0,0,0,0,0,0,0,0,1,0,0,0,0,0,0,0,0,0,1,0,0,0,0,0,0,0,0
0,0,0,0,0,0,0,0,0,1,1,21,0,0,0,21,1,1,0,0,0,0,0,0,0,0,0
0,0,0,0,0,0,0,0,0,0,0,0,0,0,0,0,0,0,0,0,0,0,0,0,0,0,0
0,0,0,0,0,0,0,0,0,0,0,0,0,0,0,0,0,0,0,0,0,0,0,0,0,0,0
endlayer

layer
0,0,0,0,0,0,0,0,0,0,0,0,0,0,0,0,0,0,0,0,0,0,0,0,0,0,0
0,0,0,0,0,0,0,0,0,0,0,0,0,0,0,0,0,0,0,0,0,0,0,0,0,0,0
0,0,0,0,0,0,0,0,1,1,1,1,0,0,0,1,1,1,1,0,0,0,0,0,0,0,0
0,0,0,0,0,0,0,1,1,0,0,0,0,0,0,0,0,0,1,1,0,0,0,0,0,0,0
0,0,0,0,0,0,1,1,0,0,0,0,0,0,0,0,0,0,0,1,1,0,0,0,0,0,0
0,0,0,0,0,1,1,0,0,0,0,0,0,0,0,0,0,0,0,0,1,1,0,0,0,0,0
0,0,0,0,1,1,0,0,0,0,0,6,6,0,6,6,0,0,0,0,0,1,1,0,0,0,0
0,0,0,1,1,0,0,0,6,0,0,6,2,2,2,6,0,0,6,0,0,0,1,1,0,0,0
0,0,1,1,0,0,0,6,6,0,0,0,0,0,0,0,0,0,6,6,0,0,0,1,1,0,0
0,0,1,0,0,0,0,0,0,0,0,0,0,0,0,0,0,0,0,0,0,0,0,0,1,0,0
0,0,1,0,0,0,0,0,0,0,0,0,0,0,0,0,0,0,0,0,0,0,0,0,1,0,0
0,0,1,0,0,0,0,0,21,1,1,1,0,0,0,0,0,0,0,0,0,0,0,0,1,0,0
0,0,1,0,0,0,0,0,22,9,0,0,0,0,0,0,0,0,0,0,0,0,0,0,0,0,0
0,0,1,0,0,0,0,0,22,9,0,0,0,0,0,0,0,0,0,0,0,0,0,0,0,0,0
0,0,1,0,0,0,0,0,22,9,0,0,0,0,0,0,0,0,0,0,0,0,0,0,0,0,0
0,0,1,0,0,0,0,0,21,1,1,1,0,0,0,0,0,0,0,0,0,0,0,0,1,0,0
0,0,1,0,0,0,0,0,0,0,0,0,0,0,0,0,0,0,0,0,0,0,0,0,1,0,0
0,0,1,0,0,0,0,0,0,0,0,0,0,0,0,0,0,0,0,0,0,0,0,0,1,0,0
0,0,1,1,0,0,0,6,6,0,0,0,0,0,0,0,0,0,6,6,0,0,0,1,1,0,0
0,0,0,1,1,0,0,0,6,0,0,6,2,2,2,6,0,0,6,0,0,0,1,1,0,0,0
0,0,0,0,1,1,0,0,0,0,0,6,6,0,6,6,0,0,0,0,0,1,1,0,0,0,0
0,0,0,0,0,1,1,0,0,0,0,0,0,0,0,0,0,0,0,0,1,1,0,0,0,0,0
0,0,0,0,0,0,1,1,0,0,0,0,0,0,0,0,0,0,0,1,1,0,0,0,0,0,0
0,0,0,0,0,0,0,1,1,0,0,0,0,0,0,0,0,0,1,1,0,0,0,0,0,0,0
0,0,0,0,0,0,0,0,1,1,1,1,0,0,0,1,1,1,1,0,0,0,0,0,0,0,0
0,0,0,0,0,0,0,0,0,0,0,0,0,0,0,0,0,0,0,0,0,0,0,0,0,0,0
0,0,0,0,0,0,0,0,0,0,0,0,0,0,0,0,0,0,0,0,0,0,0,0,0,0,0
endlayer

layer
0,0,0,0,0,0,0,0,0,0,0,0,0,0,0,0,0,0,0,0,0,0,0,0,0,0,0
0,0,0,0,0,0,0,0,0,0,0,0,0,0,0,0,0,0,0,0,0,0,0,0,0,0,0
0,0,0,0,0,0,0,0,1,1,1,1,1,21,1,1,1,1,1,0,0,0,0,0,0,0,0
0,0,0,0,0,0,0,1,1,0,0,0,0,0,0,0,0,0,1,1,0,0,0,0,0,0,0
0,0,0,0,0,0,1,1,0,0,0,0,0,0,0,0,0,0,0,1,1,0,0,0,0,0,0
0,0,0,0,0,1,1,0,0,0,0,0,0,0,0,0,0,0,0,0,1,1,0,0,0,0,0
0,0,0,0,1,1,0,0,6,0,0,6,21,21,21,6,0,0,6,0,0,1,1,0,0,0,0
0,0,0,1,1,0,0,0,6,0,0,6,2,2,2,6,0,0,6,0,0,0,1,1,0,0,0
0,0,1,1,0,0,6,6,6,0,0,6,24,24,24,6,0,0,6,6,6,0,0,1,1,0,0
0,0,1,0,0,0,0,0,0,0,0,0,0,0,0,0,0,0,0,0,0,0,0,0,1,0,0
0,0,1,0,0,0,0,0,0,0,0,0,0,0,0,0,0,0,0,0,0,0,0,0,1,0,0
0,0,1,0,0,0,0,21,1,1,1,0,0,0,0,0,0,0,0,0,0,0,0,0,1,0,0
0,0,1,0,0,0,0,22,9,0,0,0,0,0,0,0,0,0,0,0,21,0,0,0,1,0,0
0,0,1,0,0,0,0,22,9,0,0,0,0,0,0,0,0,0,0,0,21,0,0,0,21,0,0
0,0,1,0,0,0,0,22,9,0,0,0,0,0,0,0,0,0,0,0,21,0,0,0,1,0,0
0,0,1,0,0,0,0,21,1,1,1,0,0,0,0,0,0,0,0,0,0,0,0,0,1,0,0
0,0,1,0,0,0,0,0,0,0,0,0,0,0,0,0,0,0,0,0,0,0,0,0,1,0,0
0,0,1,0,0,0,0,0,0,0,0,0,0,0,0,0,0,0,0,0,0,0,0,0,1,0,0
0,0,1,1,0,0,6,6,6,0,0,6,24,24,24,6,0,0,6,6,6,0,0,1,1,0,0
0,0,0,1,1,0,0,0,6,0,0,6,2,2,2,6,0,0,6,0,0,0,1,1,0,0,0
0,0,0,0,1,1,0,0,6,0,0,6,21,21,21,6,0,0,6,0,0,1,1,0,0,0,0
0,0,0,0,0,1,1,0,0,0,0,0,0,0,0,0,0,0,0,0,1,1,0,0,0,0,0
0,0,0,0,0,0,1,1,0,0,0,0,0,0,0,0,0,0,0,1,1,0,0,0,0,0,0
0,0,0,0,0,0,0,1,1,0,0,0,0,0,0,0,0,0,1,1,0,0,0,0,0,0,0
0,0,0,0,0,0,0,0,1,1,1,1,1,21,1,1,1,1,1,0,0,0,0,0,0,0,0
0,0,0,0,0,0,0,0,0,0,0,0,0,0,0,0,0,0,0,0,0,0,0,0,0,0,0
0,0,0,0,0,0,0,0,0,0,0,0,0,0,0,0,0,0,0,0,0,0,0,0,0,0,0
endlayer

layer
0,0,0,0,0,0,0,0,0,0,0,0,0,0,0,0,0,0,0,0,0,0,0,0,0,0,0
0,0,0,0,0,0,0,0,0,0,0,0,0,0,0,0,0,0,0,0,0,0,0,0,0,0,0
0,0,0,0,0,0,0,1,1,1,1,1,1,1,1,1,1,1,1,1,0,0,0,0,0,0,0
0,0,0,0,0,0,1,1,1,0,0,0,0,0,0,0,0,0,1,1,1,0,0,0,0,0,0
0,0,0,0,0,1,1,1,0,0,0,0,0,0,0,0,0,0,0,1,1,1,0,0,0,0,0
0,0,0,0,1,1,1,0,0,0,0,26,26,26,26,25,0,0,0,0,1,1,1,0,0,0,0
0,0,0,1,1,1,0,0,6,0,0,22,27,27,27,25,0,0,6,0,0,1,1,1,0,0,0
0,0,1,1,1,0,0,0,0,26,26,26,2,2,2,26,26,25,0,0,0,0,1,1,1,0,0
0,0,1,1,0,0,6,0,6,22,1,1,1,1,1,1,1,25,6,0,6,0,0,1,1,0,0
0,0,1,0,0,0,26,26,26,22,1,0,0,0,0,0,1,25,26,25,0,0,0,0,1,0,0
0,0,1,0,0,0,22,1,1,1,1,0,0,0,0,0,1,1,1,25,0,0,0,0,1,0,0
0,0,1,0,0,0,1,1,1,1,0,0,0,0,0,0,0,0,1,25,26,26,0,0,1,0,0
0,0,1,0,0,0,22,9,0,0,0,0,0,0,0,0,0,0,1,0,0,25,0,0,1,0,0
0,0,1,0,0,0,22,9,0,0,0,0,0,0,0,0,0,0,1,0,0,25,0,0,1,0,0
0,0,1,0,0,0,22,9,0,0,0,0,0,0,0,0,0,0,1,0,0,25,0,0,1,0,0
0,0,1,0,0,0,1,1,1,1,0,0,0,0,0,0,0,0,1,25,28,28,0,0,1,0,0
0,0,1,0,0,0,22,1,1,1,1,0,0,0,0,0,1,1,1,25,0,0,0,0,1,0,0
0,0,1,0,0,0,28,28,28,28,1,0,0,0,0,0,1,25,28,28,0,0,0,0,1,0,0
0,0,21,1,0,0,6,0,6,22,1,1,1,1,1,1,1,25,6,0,6,0,0,1,1,0,0
0,0,1,21,1,0,0,0,0,22,28,22,2,2,2,25,28,28,0,0,0,0,1,1,1,0,0
0,0,0,1,21,1,0,0,6,0,0,22,27,27,27,25,0,0,6,0,0,1,1,1,0,0,0
0,0,0,0,1,21,1,0,0,0,0,22,28,28,28,28,0,0,0,0,1,1,1,0,0,0,0
0,0,0,0,0,1,1,1,0,0,0,0,0,0,0,0,0,0,0,1,1,1,0,0,0,0,0
0,0,0,0,0,0,1,1,1,0,0,0,0,0,0,0,0,0,1,1,1,0,0,0,0,0,0
0,0,0,0,0,0,0,1,1,1,1,1,1,1,1,1,1,1,1,1,0,0,0,0,0,0,0
0,0,0,0,0,0,0,0,0,0,0,0,0,0,0,0,0,0,0,0,0,0,0,0,0,0,0
0,0,0,0,0,0,0,0,0,0,0,0,0,0,0,0,0,0,0,0,0,0,0,0,0,0,0
endlayer

layer
0,0,0,0,0,0,0,0,0,0,0,0,0,0,0,0,0,0,0,0,0,0,0,0,0,0,0
0,0,0,0,0,0,0,0,0,0,0,0,0,0,0,0,0,0,0,0,0,0,0,0,0,0,0
0,0,0,0,0,0,0,1,1,1,1,1,1,1,1,1,1,1,1,1,0,0,0,0,0,0,0
0,0,0,0,0,0,1,1,1,1,1,1,1,1,1,1,1,1,1,1,1,0,0,0,0,0,0
0,0,0,0,0,1,1,1,1,1,1,1,19,19,19,1,1,1,1,1,1,1,0,0,0,0,0
0,0,0,0,1,1,1,1,1,1,1,19,21,21,21,11,1,1,1,1,1,1,1,0,0,0,0
0,0,0,1,1,1,1,1,1,1,1,9,21,21,21,11,1,1,1,1,1,1,1,1,0,0,0
0,0,1,1,1,1,1,1,1,19,19,9,21,21,21,19,19,11,1,1,1,1,1,1,1,0,0
0,0,1,1,1,1,1,1,1,9,0,0,0,0,0,0,0,11,1,1,1,1,1,1,1,0,0
0,0,1,1,1,1,1,19,19,19,0,0,0,0,0,0,0,19,19,11,1,1,1,1,1,0,0
0,0,1,1,1,1,1,9,0,0,0,0,0,0,0,0,0,0,0,11,1,1,1,1,1,0,0
0,0,1,1,1,1,19,19,0,0,0,0,0,0,0,0,0,0,0,19,19,11,1,1,1,0,0
0,0,1,1,1,1,9,0,0,0,0,0,0,0,0,0,0,0,0,21,21,11,1,1,1,0,0
0,0,1,1,1,1,9,0,0,0,0,0,0,0,0,0,0,0,0,21,21,11,1,1,1,0,0
0,0,1,1,1,1,9,0,0,0,0,0,0,0,0,0,0,0,0,21,21,11,1,1,1,0,0
0,0,1,1,1,1,10,10,0,0,0,0,0,0,0,0,0,0,0,11,10,10,1,1,1,0,0
0,0,1,1,1,1,1,9,0,0,0,0,0,0,0,0,0,0,0,11,1,1,1,1,1,0,0
0,0,1,1,1,1,1,10,10,9,0,0,0,0,0,0,0,11,10,10,1,1,1,1,1,0,0
0,0,1,1,1,1,1,1,1,9,0,0,0,0,0,0,0,11,1,1,1,1,1,1,1,0,0
0,0,21,1,1,1,1,1,1,10,10,9,21,21,21,11,10,10,1,1,1,1,1,1,1,0,0
0,0,0,21,1,1,1,1,1,1,1,9,21,21,21,11,1,1,1,1,1,1,1,1,0,0,0
0,0,0,0,21,1,1,1,1,1,1,9,21,21,21,10,1,1,1,1,1,1,1,0,0,0,0
0,0,0,0,0,1,1,1,1,1,1,1,10,10,10,1,1,1,1,1,1,1,0,0,0,0,0
0,0,0,0,0,0,1,1,1,1,1,1,1,1,1,1,1,1,1,1,1,0,0,0,0,0,0
0,0,0,0,0,0,0,1,1,1,1,1,1,1,1,1,1,1,1,1,0,0,0,0,0,0,0
0,0,0,0,0,0,0,0,0,0,0,0,0,0,0,0,0,0,0,0,0,0,0,0,0,0,0
0,0,0,0,0,0,0,0,0,0,0,0,0,0,0,0,0,0,0,0,0,0,0,0,0,0,0
endlayer

layer
0,0,0,0,0,0,0,0,0,22,26,26,26,26,26,26,26,25,0,0,0,0,0,0,0,0,0
0,0,0,0,0,0,22,26,26,22,19,19,19,19,19,19,19,25,26,26,26,0,0,0,0,0,0
0,0,0,0,0,22,26,9,19,19,9,0,0,0,0,0,11,19,19,11,25,26,0,0,0,0,0
0,0,0,0,22,26,9,19,0,0,0,0,0,0,0,0,0,0,0,11,19,25,26,0,0,0,0
0,0,0,22,26,9,19,0,0,0,0,0,0,0,0,0,0,0,0,0,11,19,25,26,0,0,0
0,0,22,26,9,19,0,0,0,0,0,0,0,0,0,0,0,0,0,0,0,11,19,25,26,0,0
0,22,26,9,19,0,0,0,10,0,0,0,0,0,0,0,0,0,10,0,0,0,11,19,25,26,0
0,22,9,19,0,0,0,21,25,0,0,0,0,0,0,0,0,0,22,21,0,0,0,11,19,25,0
0,22,9,0,0,0,11,28,6,0,0,0,0,0,0,0,0,0,6,28,9,0,0,0,11,25,0
22,26,9,0,0,0,0,0,0,0,0,0,0,0,0,0,0,0,0,0,0,0,0,0,11,26,26
22,9,19,0,0,0,0,0,0,0,0,0,0,0,0,0,0,0,0,0,0,0,0,0,19,11,25
22,9,0,0,0,0,0,0,0,0,0,0,0,0,0,0,0,0,0,0,0,0,0,0,0,11,25
22,9,0,0,0,0,0,0,0,0,0,0,0,0,0,0,0,0,0,0,0,0,0,0,0,11,25
22,9,0,0,0,0,0,0,0,0,0,0,0,0,0,0,0,0,0,0,0,0,0,0,0,11,25
22,9,0,0,0,0,0,0,0,0,0,0,0,0,0,0,0,0,0,0,0,0,0,0,0,11,25
22,9,0,0,0,0,0,0,0,0,0,0,0,0,0,0,0,0,0,0,0,0,0,0,0,11,25
22,9,10,0,0,0,0,0,0,0,0,0,0,0,0,0,0,0,0,0,0,0,0,0,10,11,25
28,28,9,0,0,0,0,0,0,0,0,0,0,0,0,0,0,0,0,0,0,0,0,0,11,28,28
0,22,9,0,0,0,11,26,6,0,0,0,0,0,0,0,0,0,6,26,9,0,0,0,11,25,0
0,22,10,9,0,0,0,21,25,0,0,0,0,0,0,0,0,0,22,21,0,0,0,10,11,25,0
0,28,22,10,9,0,0,0,19,0,0,0,0,0,0,0,0,0,19,0,0,0,10,11,28,28,0
0,0,28,22,10,9,0,0,0,0,0,0,0,0,0,0,0,0,0,0,0,10,11,28,25,0,0
0,0,0,28,22,10,9,0,0,0,0,0,0,0,0,0,0,0,0,0,10,11,28,25,0,0,0
0,0,0,0,28,22,10,9,0,0,0,0,0,0,0,0,0,0,0,10,11,28,25,0,0,0,0
0,0,0,0,0,28,22,10,10,10,9,0,0,0,0,0,11,10,10,11,28,25,0,0,0,0,0
0,0,0,0,0,0,22,28,28,22,10,10,10,10,10,10,10,25,28,28,25,0,0,0,0,0,0
0,0,0,0,0,0,0,0,0,22,28,28,28,28,28,28,28,28,0,0,0,0,0,0,0,0,0
endlayer

layer
0,0,0,0,0,0,0,0,0,1,1,1,1,1,1,1,1,1,0,0,0,0,0,0,0,0,0
0,0,0,0,0,0,1,1,1,1,0,0,0,0,0,0,0,1,1,1,1,0,0,0,0,0,0
0,0,0,0,0,1,1,0,0,0,0,0,0,0,0,0,0,0,0,0,1,1,0,0,0,0,0
0,0,0,0,1,1,0,0,0,0,0,0,0,0,0,0,0,0,0,0,0,1,1,0,0,0,0
0,0,0,1,1,0,0,0,0,0,0,0,0,0,0,0,0,0,0,0,0,0,1,1,0,0,0
0,0,1,1,0,0,0,0,0,0,0,0,0,0,0,0,0,0,0,0,0,0,0,1,1,0,0
0,1,1,0,0,0,0,0,0,0,0,0,0,0,0,0,0,0,0,0,0,0,0,0,1,1,0
0,1,0,0,0,0,0,0,10,0,0,0,0,0,0,0,0,0,10,0,0,0,0,0,0,1,0
0,1,0,0,0,0,0,11,6,0,0,0,0,0,0,0,0,0,6,9,0,0,0,0,0,1,0
1,1,0,0,0,0,0,0,0,0,0,0,0,0,0,0,0,0,0,0,0,0,0,0,0,1,1
1,0,0,0,0,0,0,0,0,0,0,0,0,0,0,0,0,0,0,0,0,0,0,0,0,0,1
1,0,0,0,0,0,0,0,0,0,0,0,0,0,0,0,0,0,0,0,0,0,0,0,0,0,1
1,0,0,0,0,0,0,0,0,0,0,0,0,0,0,0,0,0,0,0,0,0,0,0,0,0,1
1,0,0,0,0,0,0,0,0,0,0,0,0,0,0,0,0,0,0,0,0,0,0,0,0,0,1
1,0,0,0,0,0,0,0,0,0,0,0,0,0,0,0,0,0,0,0,0,0,0,0,0,0,1
1,0,0,0,0,0,0,0,0,0,0,0,0,0,0,0,0,0,0,0,0,0,0,0,0,0,1
1,0,0,0,0,0,0,0,0,0,0,0,0,0,0,0,0,0,0,0,0,0,0,0,0,0,1
1,1,0,0,0,0,0,0,0,0,0,0,0,0,0,0,0,0,0,0,0,0,0,0,0,1,1
0,1,0,0,0,0,0,11,6,0,0,0,0,0,0,0,0,0,6,9,0,0,0,0,0,1,0
0,1,0,0,0,0,0,0,19,0,0,0,0,0,0,0,0,0,19,0,0,0,0,0,0,1,0
0,1,1,0,0,0,0,0,0,0,0,0,0,0,0,0,0,0,0,0,0,0,0,0,1,1,0
0,0,1,1,0,0,0,0,0,0,0,0,0,0,0,0,0,0,0,0,0,0,0,1,1,0,0
0,0,0,1,1,0,0,0,0,0,0,0,0,0,0,0,0,0,0,0,0,0,1,1,0,0,0
0,0,0,0,1,1,0,0,0,0,0,0,0,0,0,0,0,0,0,0,0,1,1,0,0,0,0
0,0,0,0,0,1,1,0,0,0,0,0,0,0,0,0,0,0,0,0,1,1,0,0,0,0,0
0,0,0,0,0,0,1,1,1,1,0,0,0,0,0,0,0,1,1,1,1,0,0,0,0,0,0
0,0,0,0,0,0,0,0,0,1,1,1,1,1,1,1,1,1,0,0,0,0,0,0,0,0,0
endlayer

layer
0,0,0,0,0,0,0,0,0,0,0,0,0,0,0,0,0,0,0,0,0,0,0,0,0,0,0
0,0,0,0,0,0,0,0,0,0,0,0,0,0,0,0,0,0,0,0,0,0,0,0,0,0,0
0,0,0,0,0,0,0,0,0,0,0,0,0,0,0,0,0,0,0,0,0,0,0,0,0,0,0
0,0,0,0,0,0,0,0,0,0,0,0,0,0,0,0,0,0,0,0,0,0,0,0,0,0,0
0,0,0,0,0,0,0,0,0,0,0,0,0,0,0,0,0,0,0,0,0,0,0,0,0,0,0
0,0,0,0,0,0,0,0,0,0,0,0,0,0,0,0,0,0,0,0,0,0,0,0,0,0,0
0,0,0,0,0,0,0,0,0,0,0,0,0,0,0,0,0,0,0,0,0,0,0,0,0,0,0
0,0,0,0,0,0,0,0,0,6,0,0,0,0,0,0,0,6,0,0,0,0,0,0,0,0,0
0,0,0,0,0,0,0,0,1,6,6,0,0,0,0,0,6,6,1,0,0,0,0,0,0,0,0
0,0,0,0,0,0,0,6,6,0,0,0,0,0,0,0,0,0,6,6,0,0,0,0,0,0,0
0,0,0,0,0,0,0,0,6,0,0,0,0,0,0,0,0,0,6,0,0,0,0,0,0,0,0
0,0,0,0,0,0,0,0,0,0,0,0,0,0,0,0,0,0,0,0,0,0,0,0,0,0,0
0,0,0,0,0,0,0,0,0,0,0,0,0,0,0,0,0,0,0,0,0,0,0,0,0,0,0
0,0,0,0,0,0,0,0,0,0,0,0,0,0,0,0,0,0,0,0,0,0,0,0,0,0,0
0,0,0,0,0,0,0,0,0,0,0,0,0,0,0,0,0,0,0,0,0,0,0,0,0,0,0
0,0,0,0,0,0,0,0,0,0,0,0,0,0,0,0,0,0,0,0,0,0,0,0,0,0,0
0,0,0,0,0,0,0,0,6,0,0,0,0,0,0,0,0,0,6,0,0,0,0,0,0,0,0
0,0,0,0,0,0,0,6,6,0,0,0,0,0,0,0,0,0,6,6,0,0,0,0,0,0,0
0,0,0,0,0,0,0,0,1,6,6,0,0,0,0,0,6,6,1,0,0,0,0,0,0,0,0
0,0,0,0,0,0,0,0,0,6,0,0,0,0,0,0,0,6,0,0,0,0,0,0,0,0,0
0,0,0,0,0,0,0,0,0,0,0,0,0,0,0,0,0,0,0,0,0,0,0,0,0,0,0
0,0,0,0,0,0,0,0,0,0,0,0,0,0,0,0,0,0,0,0,0,0,0,0,0,0,0
0,0,0,0,0,0,0,0,0,0,0,0,0,0,0,0,0,0,0,0,0,0,0,0,0,0,0
0,0,0,0,0,0,0,0,0,0,0,0,0,0,0,0,0,0,0,0,0,0,0,0,0,0,0
0,0,0,0,0,0,0,0,0,0,0,0,0,0,0,0,0,0,0,0,0,0,0,0,0,0,0
0,0,0,0,0,0,0,0,0,0,0,0,0,0,0,0,0,0,0,0,0,0,0,0,0,0,0
0,0,0,0,0,0,0,0,0,0,0,0,0,0,0,0,0,0,0,0,0,0,0,0,0,0,0
endlayer

layer
0,0,0,0,0,0,0,0,0,0,0,0,0,0,0,0,0,0,0,0,0,0,0,0,0,0,0
0,0,0,0,0,0,0,0,0,0,0,0,0,0,0,0,0,0,0,0,0,0,0,0,0,0,0
0,0,0,0,0,0,0,0,0,0,0,0,0,0,0,0,0,0,0,0,0,0,0,0,0,0,0
0,0,0,0,0,0,0,0,0,0,0,0,0,0,0,0,0,0,0,0,0,0,0,0,0,0,0
0,0,0,0,0,0,0,0,0,0,0,0,0,0,0,0,0,0,0,0,0,0,0,0,0,0,0
0,0,0,0,0,0,0,0,0,0,0,0,0,0,0,0,0,0,0,0,0,0,0,0,0,0,0
0,0,0,0,0,0,0,0,0,10,10,10,10,10,10,10,10,9,0,0,0,0,0,0,0,0,0
0,0,0,0,0,0,0,0,0,11,0,0,0,0,0,0,0,9,0,0,0,0,0,0,0,0,0
0,0,0,0,0,0,0,0,0,11,6,6,6,0,6,6,6,9,0,0,0,0,0,0,0,0,0
0,0,0,0,0,0,10,10,10,11,0,0,0,0,0,0,0,9,10,10,10,0,0,0,0,0,0
0,0,0,0,0,0,11,0,6,0,0,0,0,0,0,0,0,0,6,0,9,0,0,0,0,0,0
0,0,0,0,0,0,11,0,6,0,0,0,0,0,0,0,0,0,6,0,9,0,0,0,0,0,0
0,0,0,0,0,0,11,0,6,0,0,0,0,0,0,0,0,0,6,0,9,0,0,0,0,0,0
0,0,0,0,0,0,11,0,0,0,0,0,0,0,0,0,0,0,0,0,9,0,0,0,0,0,0
0,0,0,0,0,0,11,0,6,0,0,0,0,0,0,0,0,0,6,0,9,0,0,0,0,0,0
0,0,0,0,0,0,11,0,6,0,0,0,0,0,0,0,0,0,6,0,9,0,0,0,0,0,0
0,0,0,0,0,0,11,0,6,0,0,0,0,0,0,0,0,0,6,0,9,0,0,0,0,0,0
0,0,0,0,0,0,19,19,19,19,0,0,0,0,0,0,0,19,19,19,19,0,0,0,0,0,0
0,0,0,0,0,0,0,0,0,11,6,6,6,0,6,6,6,9,0,0,0,0,0,0,0,0,0
0,0,0,0,0,0,0,0,0,11,0,0,0,0,0,0,0,9,0,0,0,0,0,0,0,0,0
0,0,0,0,0,0,0,0,0,11,19,19,19,19,19,19,19,9,0,0,0,0,0,0,0,0,0
0,0,0,0,0,0,0,0,0,0,0,0,0,0,0,0,0,0,0,0,0,0,0,0,0,0,0
0,0,0,0,0,0,0,0,0,0,0,0,0,0,0,0,0,0,0,0,0,0,0,0,0,0,0
0,0,0,0,0,0,0,0,0,0,0,0,0,0,0,0,0,0,0,0,0,0,0,0,0,0,0
0,0,0,0,0,0,0,0,0,0,0,0,0,0,0,0,0,0,0,0,0,0,0,0,0,0,0
0,0,0,0,0,0,0,0,0,0,0,0,0,0,0,0,0,0,0,0,0,0,0,0,0,0,0
0,0,0,0,0,0,0,0,0,0,0,0,0,0,0,0,0,0,0,0,0,0,0,0,0,0,0
endlayer

layer
0,0,0,0,0,0,0,0,0,0,0,0,0,0,0,0,0,0,0,0,0,0,0,0,0,0,0
0,0,0,0,0,0,0,0,0,0,0,0,0,0,0,0,0,0,0,0,0,0,0,0,0,0,0
0,0,0,0,0,0,0,0,0,0,0,0,0,0,0,0,0,0,0,0,0,0,0,0,0,0,0
0,0,0,0,0,0,0,0,0,0,0,0,0,0,0,0,0,0,0,0,0,0,0,0,0,0,0
0,0,0,0,0,0,0,0,0,0,0,0,0,0,0,0,0,0,0,0,0,0,0,0,0,0,0
0,0,0,0,0,0,0,0,0,0,0,0,0,0,0,0,0,0,0,0,0,0,0,0,0,0,0
0,0,0,0,0,0,0,0,0,0,0,0,0,0,0,0,0,0,0,0,0,0,0,0,0,0,0
0,0,0,0,0,0,0,0,0,0,10,10,10,10,10,10,10,0,0,0,0,0,0,0,0,0,0
0,0,0,0,0,0,0,0,0,0,11,0,6,6,6,0,9,0,0,0,0,0,0,0,0,0,0
0,0,0,0,0,0,0,0,0,0,11,0,6,0,6,0,9,0,0,0,0,0,0,0,0,0,0
0,0,0,0,0,0,0,11,10,10,11,0,6,0,6,0,9,10,10,9,0,0,0,0,0,0,0
0,0,0,0,0,0,0,11,0,0,0,0,0,0,0,0,0,0,0,9,0,0,0,0,0,0,0
0,0,0,0,0,0,0,11,6,6,6,0,0,0,0,0,6,6,6,9,0,0,0,0,0,0,0
0,0,0,0,0,0,0,11,6,0,0,0,0,0,0,0,0,0,6,9,0,0,0,0,0,0,0
0,0,0,0,0,0,0,11,6,6,6,0,0,0,0,0,6,6,6,9,0,0,0,0,0,0,0
0,0,0,0,0,0,0,11,0,0,0,0,0,0,0,0,0,0,0,9,0,0,0,0,0,0,0
0,0,0,0,0,0,0,11,19,19,19,0,6,0,6,0,19,19,19,9,0,0,0,0,0,0,0
0,0,0,0,0,0,0,0,0,0,11,0,6,0,6,0,9,0,0,0,0,0,0,0,0,0,0
0,0,0,0,0,0,0,0,0,0,11,0,6,6,6,0,9,0,0,0,0,0,0,0,0,0,0
0,0,0,0,0,0,0,0,0,0,19,19,19,19,19,19,19,0,0,0,0,0,0,0,0,0,0
0,0,0,0,0,0,0,0,0,0,0,0,0,0,0,0,0,0,0,0,0,0,0,0,0,0,0
0,0,0,0,0,0,0,0,0,0,0,0,0,0,0,0,0,0,0,0,0,0,0,0,0,0,0
0,0,0,0,0,0,0,0,0,0,0,0,0,0,0,0,0,0,0,0,0,0,0,0,0,0,0
0,0,0,0,0,0,0,0,0,0,0,0,0,0,0,0,0,0,0,0,0,0,0,0,0,0,0
0,0,0,0,0,0,0,0,0,0,0,0,0,0,0,0,0,0,0,0,0,0,0,0,0,0,0
0,0,0,0,0,0,0,0,0,0,0,0,0,0,0,0,0,0,0,0,0,0,0,0,0,0,0
0,0,0,0,0,0,0,0,0,0,0,0,0,0,0,0,0,0,0,0,0,0,0,0,0,0,0
endlayer

layer
0,0,0,0,0,0,0,0,0,0,0,0,0,0,0,0,0,0,0,0,0,0,0,0,0,0,0
0,0,0,0,0,0,0,0,0,0,0,0,0,0,0,0,0,0,0,0,0,0,0,0,0,0,0
0,0,0,0,0,0,0,0,0,0,0,0,0,0,0,0,0,0,0,0,0,0,0,0,0,0,0
0,0,0,0,0,0,0,0,0,0,0,0,0,0,0,0,0,0,0,0,0,0,0,0,0,0,0
0,0,0,0,0,0,0,0,0,0,0,0,0,0,0,0,0,0,0,0,0,0,0,0,0,0,0
0,0,0,0,0,0,0,0,0,0,0,0,0,0,0,0,0,0,0,0,0,0,0,0,0,0,0
0,0,0,0,0,0,0,0,0,0,0,0,0,0,0,0,0,0,0,0,0,0,0,0,0,0,0
0,0,0,0,0,0,0,0,0,0,0,0,0,0,0,0,0,0,0,0,0,0,0,0,0,0,0
0,0,0,0,0,0,0,0,0,0,0,11,10,10,10,9,0,0,0,0,0,0,0,0,0,0,0
0,0,0,0,0,0,0,0,0,0,0,11,1,1,1,9,0,0,0,0,0,0,0,0,0,0,0
0,0,0,0,0,0,0,0,0,0,0,11,1,1,1,9,0,0,0,0,0,0,0,0,0,0,0
0,0,0,0,0,0,0,0,10,10,10,10,28,28,28,10,10,10,10,0,0,0,0,0,0,0,0
0,0,0,0,0,0,0,0,11,1,1,25,0,0,0,22,1,1,9,0,0,0,0,0,0,0,0
0,0,0,0,0,0,0,0,11,1,1,25,0,0,0,22,1,1,9,0,0,0,0,0,0,0,0
0,0,0,0,0,0,0,0,11,1,1,25,0,0,0,22,1,1,9,0,0,0,0,0,0,0,0
0,0,0,0,0,0,0,0,19,19,19,11,26,26,26,19,19,19,19,0,0,0,0,0,0,0,0
0,0,0,0,0,0,0,0,0,0,0,11,1,1,1,9,0,0,0,0,0,0,0,0,0,0,0
0,0,0,0,0,0,0,0,0,0,0,11,1,1,1,9,0,0,0,0,0,0,0,0,0,0,0
0,0,0,0,0,0,0,0,0,0,0,11,19,19,19,9,0,0,0,0,0,0,0,0,0,0,0
0,0,0,0,0,0,0,0,0,0,0,0,0,0,0,0,0,0,0,0,0,0,0,0,0,0,0
0,0,0,0,0,0,0,0,0,0,0,0,0,0,0,0,0,0,0,0,0,0,0,0,0,0,0
0,0,0,0,0,0,0,0,0,0,0,0,0,0,0,0,0,0,0,0,0,0,0,0,0,0,0
0,0,0,0,0,0,0,0,0,0,0,0,0,0,0,0,0,0,0,0,0,0,0,0,0,0,0
0,0,0,0,0,0,0,0,0,0,0,0,0,0,0,0,0,0,0,0,0,0,0,0,0,0,0
0,0,0,0,0,0,0,0,0,0,0,0,0,0,0,0,0,0,0,0,0,0,0,0,0,0,0
0,0,0,0,0,0,0,0,0,0,0,0,0,0,0,0,0,0,0,0,0,0,0,0,0,0,0
0,0,0,0,0,0,0,0,0,0,0,0,0,0,0,0,0,0,0,0,0,0,0,0,0,0,0
endlayer

layer
0,0,0,0,0,0,0,0,0,0,0,0,0,0,0,0,0,0,0,0,0,0,0,0,0,0,0
0,0,0,0,0,0,0,0,0,0,0,0,0,0,0,0,0,0,0,0,0,0,0,0,0,0,0
0,0,0,0,0,0,0,0,0,0,0,0,0,0,0,0,0,0,0,0,0,0,0,0,0,0,0
0,0,0,0,0,0,0,0,0,0,0,0,0,0,0,0,0,0,0,0,0,0,0,0,0,0,0
0,0,0,0,0,0,0,0,0,0,0,0,0,0,0,0,0,0,0,0,0,0,0,0,0,0,0
0,0,0,0,0,0,0,0,0,0,0,0,0,0,0,0,0,0,0,0,0,0,0,0,0,0,0
0,0,0,0,0,0,0,0,0,0,0,0,0,0,0,0,0,0,0,0,0,0,0,0,0,0,0
0,0,0,0,0,0,0,0,0,0,0,0,0,0,0,0,0,0,0,0,0,0,0,0,0,0,0
0,0,0,0,0,0,0,0,0,0,0,0,0,0,0,0,0,0,0,0,0,0,0,0,0,0,0
0,0,0,0,0,0,0,0,0,0,0,0,0,0,0,0,0,0,0,0,0,0,0,0,0,0,0
0,0,0,0,0,0,0,0,0,0,0,0,0,6,0,0,0,0,0,0,0,0,0,0,0,0,0
0,0,0,0,0,0,0,0,0,0,0,0,0,0,0,0,0,0,0,0,0,0,0,0,0,0,0
0,0,0,0,0,0,0,0,0,0,7,8,0,0,0,0,0,0,0,0,0,0,0,0,0,0,0
0,0,0,0,0,0,0,0,0,0,6,8,0,0,0,0,6,0,0,0,0,0,0,0,0,0,0
0,0,0,0,0,0,0,0,0,0,8,7,0,0,0,0,0,0,0,0,0,0,0,0,0,0,0
0,0,0,0,0,0,0,0,0,0,0,0,8,8,0,0,0,0,0,0,0,0,0,0,0,0,0
0,0,0,0,0,0,0,0,0,0,0,0,8,6,0,0,0,0,0,0,0,0,0,0,0,0,0
0,0,0,0,0,0,0,0,0,0,0,0,0,0,0,0,0,0,0,0,0,0,0,0,0,0,0
0,0,0,0,0,0,0,0,0,0,0,0,0,0,0,0,0,0,0,0,0,0,0,0,0,0,0
0,0,0,0,0,0,0,0,0,0,0,0,0,0,0,0,0,0,0,0,0,0,0,0,0,0,0
0,0,0,0,0,0,0,0,0,0,0,0,0,0,0,0,0,0,0,0,0,0,0,0,0,0,0
0,0,0,0,0,0,0,0,0,0,0,0,0,0,0,0,0,0,0,0,0,0,0,0,0,0,0
0,0,0,0,0,0,0,0,0,0,0,0,0,0,0,0,0,0,0,0,0,0,0,0,0,0,0
0,0,0,0,0,0,0,0,0,0,0,0,0,0,0,0,0,0,0,0,0,0,0,0,0,0,0
0,0,0,0,0,0,0,0,0,0,0,0,0,0,0,0,0,0,0,0,0,0,0,0,0,0,0
0,0,0,0,0,0,0,0,0,0,0,0,0,0,0,0,0,0,0,0,0,0,0,0,0,0,0
0,0,0,0,0,0,0,0,0,0,0,0,0,0,0,0,0,0,0,0,0,0,0,0,0,0,0
endlayer

layer
0,0,0,0,0,0,0,0,0,0,0,0,0,0,0,0,0,0,0,0,0,0,0,0,0,0,0
0,0,0,0,0,0,0,0,0,0,0,0,0,0,0,0,0,0,0,0,0,0,0,0,0,0,0
0,0,0,0,0,0,0,0,0,0,0,0,0,0,0,0,0,0,0,0,0,0,0,0,0,0,0
0,0,0,0,0,0,0,0,0,0,0,0,0,0,0,0,0,0,0,0,0,0,0,0,0,0,0
0,0,0,0,0,0,0,0,0,0,0,0,0,0,0,0,0,0,0,0,0,0,0,0,0,0,0
0,0,0,0,0,0,0,0,0,0,0,0,0,0,0,0,0,0,0,0,0,0,0,0,0,0,0
0,0,0,0,0,0,0,0,0,0,0,0,0,0,0,0,0,0,0,0,0,0,0,0,0,0,0
0,0,0,0,0,0,0,0,0,0,0,0,0,0,0,0,0,0,0,0,0,0,0,0,0,0,0
0,0,0,0,0,0,0,0,0,0,0,0,0,0,0,0,0,0,0,0,0,0,0,0,0,0,0
0,0,0,0,0,0,0,0,0,0,0,0,0,0,0,0,0,0,0,0,0,0,0,0,0,0,0
0,0,0,0,0,0,0,0,0,0,0,0,0,6,0,0,0,0,0,0,0,0,0,0,0,0,0
0,0,0,0,0,0,0,0,0,0,0,0,0,6,0,0,0,0,0,0,0,0,0,0,0,0,0
0,0,0,0,0,0,0,0,0,0,0,0,0,0,0,0,0,0,0,0,0,0,0,0,0,0,0
0,0,0,0,0,0,0,0,0,0,6,6,0,0,0,6,6,0,0,0,0,0,0,0,0,0,0
0,0,0,0,0,0,0,0,0,0,0,0,0,0,0,0,0,0,0,0,0,0,0,0,0,0,0
0,0,0,0,0,0,0,0,0,0,0,0,0,6,0,0,0,0,0,0,0,0,0,0,0,0,0
0,0,0,0,0,0,0,0,0,0,0,0,0,6,0,0,0,0,0,0,0,0,0,0,0,0,0
0,0,0,0,0,0,0,0,0,0,0,0,0,0,0,0,0,0,0,0,0,0,0,0,0,0,0
0,0,0,0,0,0,0,0,0,0,0,0,0,0,0,0,0,0,0,0,0,0,0,0,0,0,0
0,0,0,0,0,0,0,0,0,0,0,0,0,0,0,0,0,0,0,0,0,0,0,0,0,0,0
0,0,0,0,0,0,0,0,0,0,0,0,0,0,0,0,0,0,0,0,0,0,0,0,0,0,0
0,0,0,0,0,0,0,0,0,0,0,0,0,0,0,0,0,0,0,0,0,0,0,0,0,0,0
0,0,0,0,0,0,0,0,0,0,0,0,0,0,0,0,0,0,0,0,0,0,0,0,0,0,0
0,0,0,0,0,0,0,0,0,0,0,0,0,0,0,0,0,0,0,0,0,0,0,0,0,0,0
0,0,0,0,0,0,0,0,0,0,0,0,0,0,0,0,0,0,0,0,0,0,0,0,0,0,0
0,0,0,0,0,0,0,0,0,0,0,0,0,0,0,0,0,0,0,0,0,0,0,0,0,0,0
0,0,0,0,0,0,0,0,0,0,0,0,0,0,0,0,0,0,0,0,0,0,0,0,0,0,0
endlayer

layer
0,0,0,0,0,0,0,0,0,0,0,0,0,0,0,0,0,0,0,0,0,0,0,0,0,0,0
0,0,0,0,0,0,0,0,0,0,0,0,0,0,0,0,0,0,0,0,0,0,0,0,0,0,0
0,0,0,0,0,0,0,0,0,0,0,0,0,0,0,0,0,0,0,0,0,0,0,0,0,0,0
0,0,0,0,0,0,0,0,0,0,0,0,0,0,0,0,0,0,0,0,0,0,0,0,0,0,0
0,0,0,0,0,0,0,0,0,0,0,0,0,0,0,0,0,0,0,0,0,0,0,0,0,0,0
0,0,0,0,0,0,0,0,0,0,0,0,0,0,0,0,0,0,0,0,0,0,0,0,0,0,0
0,0,0,0,0,0,0,0,0,0,0,0,0,0,0,0,0,0,0,0,0,0,0,0,0,0,0
0,0,0,0,0,0,0,0,0,0,0,0,0,0,0,0,0,0,0,0,0,0,0,0,0,0,0
0,0,0,0,0,0,0,0,0,0,0,0,0,0,0,0,0,0,0,0,0,0,0,0,0,0,0
0,0,0,0,0,0,0,0,0,0,0,0,0,0,0,0,0,0,0,0,0,0,0,0,0,0,0
0,0,0,0,0,0,0,0,0,0,0,0,6,6,6,0,0,0,0,0,0,0,0,0,0,0,0
0,0,0,0,0,0,0,0,0,0,0,0,0,20,0,0,0,0,0,0,0,0,0,0,0,0,0
0,0,0,0,0,0,0,0,0,0,6,0,0,0,0,0,6,0,0,0,0,0,0,0,0,0,0
0,0,0,0,0,0,0,0,0,0,6,20,0,0,0,20,6,0,0,0,0,0,0,0,0,0,0
0,0,0,0,0,0,0,0,0,0,6,0,0,0,0,0,6,0,0,0,0,0,0,0,0,0,0
0,0,0,0,0,0,0,0,0,0,0,0,0,20,0,0,0,0,0,0,0,0,0,0,0,0,0
0,0,0,0,0,0,0,0,0,0,0,0,6,6,6,0,0,0,0,0,0,0,0,0,0,0,0
0,0,0,0,0,0,0,0,0,0,0,0,0,0,0,0,0,0,0,0,0,0,0,0,0,0,0
0,0,0,0,0,0,0,0,0,0,0,0,0,0,0,0,0,0,0,0,0,0,0,0,0,0,0
0,0,0,0,0,0,0,0,0,0,0,0,0,0,0,0,0,0,0,0,0,0,0,0,0,0,0
0,0,0,0,0,0,0,0,0,0,0,0,0,0,0,0,0,0,0,0,0,0,0,0,0,0,0
0,0,0,0,0,0,0,0,0,0,0,0,0,0,0,0,0,0,0,0,0,0,0,0,0,0,0
0,0,0,0,0,0,0,0,0,0,0,0,0,0,0,0,0,0,0,0,0,0,0,0,0,0,0
0,0,0,0,0,0,0,0,0,0,0,0,0,0,0,0,0,0,0,0,0,0,0,0,0,0,0
0,0,0,0,0,0,0,0,0,0,0,0,0,0,0,0,0,0,0,0,0,0,0,0,0,0,0
0,0,0,0,0,0,0,0,0,0,0,0,0,0,0,0,0,0,0,0,0,0,0,0,0,0,0
0,0,0,0,0,0,0,0,0,0,0,0,0,0,0,0,0,0,0,0,0,0,0,0,0,0,0
endlayer

layer
0,0,0,0,0,0,0,0,0,0,0,0,0,0,0,0,0,0,0,0,0,0,0,0,0,0,0
0,0,0,0,0,0,0,0,0,0,0,0,0,0,0,0,0,0,0,0,0,0,0,0,0,0,0
0,0,0,0,0,0,0,0,0,0,0,0,0,0,0,0,0,0,0,0,0,0,0,0,0,0,0
0,0,0,0,0,0,0,0,0,0,0,0,0,0,0,0,0,0,0,0,0,0,0,0,0,0,0
0,0,0,0,0,0,0,0,0,0,0,0,0,0,0,0,0,0,0,0,0,0,0,0,0,0,0
0,0,0,0,0,0,0,0,0,0,0,0,0,0,0,0,0,0,0,0,0,0,0,0,0,0,0
0,0,0,0,0,0,0,0,0,0,0,0,0,0,0,0,0,0,0,0,0,0,0,0,0,0,0
0,0,0,0,0,0,0,0,0,0,0,0,0,0,0,0,0,0,0,0,0,0,0,0,0,0,0
0,0,0,0,0,0,0,0,0,0,0,0,0,0,0,0,0,0,0,0,0,0,0,0,0,0,0
0,0,0,0,0,0,0,0,0,0,0,0,0,0,0,0,0,0,0,0,0,0,0,0,0,0,0
0,0,0,0,0,0,0,0,0,0,0,6,6,0,6,6,0,0,0,0,0,0,0,0,0,0,0
0,0,0,0,0,0,0,0,0,0,6,22,26,26,26,26,6,0,0,0,0,0,0,0,0,0,0
0,0,0,0,0,0,0,0,0,0,6,22,0,0,0,25,6,0,0,0,0,0,0,0,0,0,0
0,0,0,0,0,0,0,0,0,0,0,22,0,0,0,25,0,0,0,0,0,0,0,0,0,0,0
0,0,0,0,0,0,0,0,0,0,6,22,0,0,0,25,6,0,0,0,0,0,0,0,0,0,0
0,0,0,0,0,0,0,0,0,0,6,22,28,28,28,25,6,0,0,0,0,0,0,0,0,0,0
0,0,0,0,0,0,0,0,0,0,0,6,6,0,6,6,0,0,0,0,0,0,0,0,0,0,0
0,0,0,0,0,0,0,0,0,0,0,0,0,0,0,0,0,0,0,0,0,0,0,0,0,0,0
0,0,0,0,0,0,0,0,0,0,0,0,0,0,0,0,0,0,0,0,0,0,0,0,0,0,0
0,0,0,0,0,0,0,0,0,0,0,0,0,0,0,0,0,0,0,0,0,0,0,0,0,0,0
0,0,0,0,0,0,0,0,0,0,0,0,0,0,0,0,0,0,0,0,0,0,0,0,0,0,0
0,0,0,0,0,0,0,0,0,0,0,0,0,0,0,0,0,0,0,0,0,0,0,0,0,0,0
0,0,0,0,0,0,0,0,0,0,0,0,0,0,0,0,0,0,0,0,0,0,0,0,0,0,0
0,0,0,0,0,0,0,0,0,0,0,0,0,0,0,0,0,0,0,0,0,0,0,0,0,0,0
0,0,0,0,0,0,0,0,0,0,0,0,0,0,0,0,0,0,0,0,0,0,0,0,0,0,0
0,0,0,0,0,0,0,0,0,0,0,0,0,0,0,0,0,0,0,0,0,0,0,0,0,0,0
0,0,0,0,0,0,0,0,0,0,0,0,0,0,0,0,0,0,0,0,0,0,0,0,0,0,0
endlayer

layer
0,0,0,0,0,0,0,0,0,0,0,0,0,0,0,0,0,0,0,0,0,0,0,0,0,0,0
0,0,0,0,0,0,0,0,0,0,0,0,0,0,0,0,0,0,0,0,0,0,0,0,0,0,0
0,0,0,0,0,0,0,0,0,0,0,0,0,0,0,0,0,0,0,0,0,0,0,0,0,0,0
0,0,0,0,0,0,0,0,0,0,0,0,0,0,0,0,0,0,0,0,0,0,0,0,0,0,0
0,0,0,0,0,0,0,0,0,0,0,0,0,0,0,0,0,0,0,0,0,0,0,0,0,0,0
0,0,0,0,0,0,0,0,0,0,0,0,0,0,0,0,0,0,0,0,0,0,0,0,0,0,0
0,0,0,0,0,0,0,0,0,0,0,0,0,0,0,0,0,0,0,0,0,0,0,0,0,0,0
0,0,0,0,0,0,0,0,0,0,0,0,0,0,0,0,0,0,0,0,0,0,0,0,0,0,0
0,0,0,0,0,0,0,0,0,0,0,0,0,0,0,0,0,0,0,0,0,0,0,0,0,0,0
0,0,0,0,0,0,0,0,0,0,0,0,0,0,0,0,0,0,0,0,0,0,0,0,0,0,0
0,0,0,0,0,0,0,0,0,0,0,6,0,0,0,6,0,0,0,0,0,0,0,0,0,0,0
0,0,0,0,0,0,0,0,0,0,6,6,0,0,0,6,6,0,0,0,0,0,0,0,0,0,0
0,0,0,0,0,0,0,0,0,0,0,0,0,0,0,0,0,0,0,0,0,0,0,0,0,0,0
0,0,0,0,0,0,0,0,0,0,0,0,0,0,0,0,0,0,0,0,0,0,0,0,0,0,0
0,0,0,0,0,0,0,0,0,0,0,0,0,0,0,0,0,0,0,0,0,0,0,0,0,0,0
0,0,0,0,0,0,0,0,0,0,6,6,0,0,0,6,6,0,0,0,0,0,0,0,0,0,0
0,0,0,0,0,0,0,0,0,0,0,6,0,0,0,6,0,0,0,0,0,0,0,0,0,0,0
0,0,0,0,0,0,0,0,0,0,0,0,0,0,0,0,0,0,0,0,0,0,0,0,0,0,0
0,0,0,0,0,0,0,0,0,0,0,0,0,0,0,0,0,0,0,0,0,0,0,0,0,0,0
0,0,0,0,0,0,0,0,0,0,0,0,0,0,0,0,0,0,0,0,0,0,0,0,0,0,0
0,0,0,0,0,0,0,0,0,0,0,0,0,0,0,0,0,0,0,0,0,0,0,0,0,0,0
0,0,0,0,0,0,0,0,0,0,0,0,0,0,0,0,0,0,0,0,0,0,0,0,0,0,0
0,0,0,0,0,0,0,0,0,0,0,0,0,0,0,0,0,0,0,0,0,0,0,0,0,0,0
0,0,0,0,0,0,0,0,0,0,0,0,0,0,0,0,0,0,0,0,0,0,0,0,0,0,0
0,0,0,0,0,0,0,0,0,0,0,0,0,0,0,0,0,0,0,0,0,0,0,0,0,0,0
0,0,0,0,0,0,0,0,0,0,0,0,0,0,0,0,0,0,0,0,0,0,0,0,0,0,0
0,0,0,0,0,0,0,0,0,0,0,0,0,0,0,0,0,0,0,0,0,0,0,0,0,0,0
endlayer

