
# Created by Ruins mod version 14.6 Ingame Parser
# authoring Player: LiquidDestiny

weight=1
embed_into_distance=5
acceptable_target_blocks=
unacceptable_target_blocks=flowing_water,water,flowing_lava,lava
dimensions=10,23,21
allowable_overhang=0
max_leveling=2
leveling_buffer=0
preserve_water=0
preserve_lava=0

rule1=0,100,minecraft:stone-0
rule2=0,100,ExtrabiomesXL:terrain_blocks2-0
rule3=0,100,minecraft:dirt-0
rule4=0,100,chisel:limestone-0
rule5=0,100,chisel:cobblestone-2
rule6=0,100,chisel:marble-0
rule7=0,100,minecraft:cobblestone-0
rule8=0,100,chisel:oak_planks-10
rule9=0,100,chisel:birch_planks-10
rule10=0,100,minecraft:wooden_door-7
rule11=0,100,minecraft:stone_stairs-2
rule12=0,100,chisel:oak_planks-11
rule13=0,100,ChestGenHook:dungeonChest:5-4
rule14=0,100,minecraft:sand-1
rule15=0,100,minecraft:wooden_door-8
rule16=0,100,Botany:soil-6
rule17=0,100,Railcraft:slab-0
rule18=0,100,Quadrum:singedPlank-3
rule19=0,100,Quadrum:deadWood-3
rule20=0,100,Quadrum:charredWood-3
rule21=0,100,Quadrum:deadWood-5
rule22=0,100,Quadrum:singedPlank-5
rule23=0,100,minecraft:gravel-0
rule24=0,100,minecraft:fence-0
rule25=0,100,Botany:plant-2
rule26=0,100,Botany:plant-1
rule27=0,100,Botany:plant-0
rule28=0,100,Quadrum:deadWood-2
rule29=0,100,Quadrum:singedSlab-0
rule30=0,100,Quadrum:charredPlank-3
rule31=0,100,Quadrum:charredPlank-5
rule32=0,100,Quadrum:charredWood-2
rule33=0,100,Quadrum:charredPlank-2
rule34=0,100,Quadrum:singedStair-5
rule35=0,100,minecraft:stone_slab-3
rule36=0,100,minecraft:furnace-5
rule37=0,100,Quadrum:singedPlank-2
rule38=0,100,ExtrabiomesXL:grass-4
rule39=0,100,Quadrum:charredWood-5
rule40=0,100,Quadrum:charredWood-4
rule41=0,100,Quadrum:singedPlank-4
rule42=0,100,Quadrum:singedSlab-8
rule43=0,100,Quadrum:charredPlank-4

layer
1,1,1,1,1,1,1,1,1,1,1,1,1,1,1,1,2,2,2,2,1
1,1,1,1,1,1,3,2,2,2,1,1,1,1,1,2,2,2,2,1,1
2,2,1,1,1,1,3,2,2,2,1,1,1,1,2,2,2,2,2,1,1
1,2,1,1,1,1,3,2,2,2,1,1,1,1,1,2,2,2,2,1,1
2,2,1,1,1,1,3,2,2,2,1,1,1,1,1,2,2,2,1,1,1
2,1,1,1,4,4,1,2,2,2,1,1,1,1,1,2,2,2,2,1,1
2,1,2,1,1,4,1,2,2,2,1,1,1,1,2,2,2,2,2,1,1
1,1,1,1,1,1,2,2,2,2,2,2,1,2,2,2,2,1,1,1,1
1,2,1,1,1,1,2,2,2,2,2,2,5,5,5,5,2,2,1,1,1
1,1,1,1,1,1,2,2,2,2,2,2,5,5,5,5,1,1,1,1,1
1,1,1,1,1,1,1,2,2,2,5,5,5,5,5,5,1,1,1,1,1
1,1,1,1,1,1,1,2,2,2,2,2,5,5,5,5,1,1,1,1,1
1,1,1,1,1,1,1,2,2,2,5,5,5,5,5,5,1,1,1,1,1
1,1,1,1,1,1,1,1,2,2,5,5,5,5,5,5,1,1,1,1,1
1,1,1,1,1,1,1,1,1,2,5,5,5,5,5,5,1,1,1,1,1
1,1,1,1,1,1,1,1,1,1,5,5,5,5,5,5,1,1,1,1,1
1,1,1,1,1,1,1,1,1,1,1,1,2,2,2,2,2,1,1,1,1
1,1,1,1,1,1,1,1,1,1,1,1,2,2,2,1,2,1,1,1,1
1,1,1,1,1,1,1,1,1,1,1,1,1,2,2,2,1,1,1,1,1
1,1,1,1,1,1,1,1,1,1,1,1,1,2,2,2,1,1,1,1,1
1,1,1,1,1,1,1,1,1,1,1,1,1,1,1,2,1,1,1,1,1
1,1,1,1,1,1,1,1,1,1,1,1,6,1,2,1,1,1,1,1,1
1,1,1,1,1,1,1,1,1,1,1,1,6,6,1,1,1,1,1,1,1
endlayer

layer
2,2,2,2,2,2,2,2,2,2,2,2,2,2,2,2,2,2,2,2,2
2,2,2,2,2,2,2,2,2,2,2,2,2,2,2,2,2,2,2,2,2
2,2,2,2,2,2,2,2,2,2,2,2,2,2,2,2,2,2,2,2,2
2,2,2,2,2,2,2,2,2,2,2,2,2,2,2,2,2,2,2,2,2
2,2,2,2,2,2,2,2,2,2,2,2,2,2,2,2,2,2,2,2,2
2,2,2,2,2,2,2,2,2,2,2,2,2,2,2,2,2,2,2,2,2
2,2,2,2,2,2,2,2,2,2,2,2,2,2,2,2,2,2,2,2,2
2,2,2,2,2,2,2,2,2,2,2,2,7,7,7,7,7,2,2,2,2
2,2,2,2,2,2,2,2,2,2,2,7,8,9,9,8,7,2,2,2,2
2,2,2,2,2,2,2,2,2,7,7,7,8,9,8,0,7,2,2,2,2
2,2,2,2,2,2,2,2,2,11,0,10,0,0,0,0,7,2,2,2,2
2,2,2,2,7,7,7,7,7,7,7,7,0,0,0,0,7,2,2,2,2
2,2,2,2,2,2,2,2,2,7,8,8,0,0,0,0,7,2,2,2,2
2,2,2,2,2,2,2,2,2,7,8,12,0,0,0,0,7,2,2,2,2
2,2,2,2,2,2,2,2,2,7,8,9,0,0,0,0,7,2,2,2,2
2,2,2,2,2,2,2,2,2,7,8,8,0,0,0,0,7,2,2,2,2
2,2,2,2,2,2,2,2,2,7,7,7,7,7,7,7,7,2,2,2,2
2,2,2,2,2,2,2,2,2,2,2,2,2,2,2,2,2,2,2,2,2
2,2,2,2,2,2,2,2,2,2,2,2,2,2,2,2,2,2,2,2,2
2,2,2,2,2,2,2,2,2,2,2,2,2,2,2,2,2,2,2,2,2
2,2,2,2,2,2,2,2,2,2,2,2,2,2,2,2,2,2,2,2,2
2,2,2,2,2,2,2,2,2,2,2,2,1,2,2,2,2,2,2,2,2
2,2,2,2,2,2,2,2,2,2,1,2,14,2,2,2,2,2,2,2,2
endlayer

layer
2,2,2,2,2,2,2,2,2,2,2,2,2,2,2,2,2,2,2,2,2
2,2,2,2,2,2,2,2,2,2,2,2,2,2,2,2,2,2,2,2,2
2,2,2,2,2,2,2,2,2,2,2,2,2,2,2,2,2,2,2,2,2
2,2,2,2,2,2,2,2,2,2,2,2,2,2,2,2,2,2,2,2,2
2,2,2,2,2,2,2,2,2,2,2,2,2,2,2,2,2,2,2,2,2
2,2,2,2,2,2,2,2,2,2,2,2,2,2,2,2,2,2,2,2,2
2,2,2,2,2,2,2,2,2,2,2,2,2,2,2,2,2,2,2,2,2
2,2,2,2,2,2,2,2,2,2,2,2,7,7,7,7,7,2,2,2,2
2,2,2,2,2,2,2,2,2,2,2,7,0,9,8,0,7,2,2,2,2
2,2,2,2,2,2,2,2,7,7,7,7,0,0,0,0,7,2,2,2,2
2,2,2,2,2,2,2,2,11,0,0,15,0,0,0,0,7,2,2,2,2
2,2,2,2,7,7,7,7,7,7,7,7,0,0,0,0,7,2,2,2,2
2,2,2,2,2,2,2,2,2,7,8,9,0,0,0,0,7,2,2,2,2
2,2,2,2,2,2,2,2,2,7,9,0,0,0,0,0,7,2,2,2,2
2,2,2,2,2,2,2,2,2,7,0,0,0,0,0,0,7,2,2,2,2
2,2,2,2,2,2,2,2,2,7,8,0,0,0,0,0,7,2,2,2,2
2,2,2,2,2,2,2,2,2,7,7,7,7,7,7,7,7,2,2,2,2
2,2,2,2,2,2,2,2,2,2,2,2,2,2,2,2,2,2,2,2,2
2,2,2,2,2,2,2,2,2,2,2,2,2,2,2,2,2,2,2,2,2
2,2,2,2,2,2,2,2,2,2,2,2,2,2,2,2,2,2,2,2,2
2,2,2,2,2,2,2,2,2,2,2,2,2,2,2,2,2,2,2,2,2
2,2,2,2,2,2,2,2,2,2,2,2,2,2,2,2,2,2,2,2,2
2,2,2,2,2,2,2,2,2,2,2,2,2,2,2,2,2,2,2,2,2
endlayer

layer
2,2,2,2,2,2,2,2,2,2,2,2,2,2,2,2,2,2,2,2,2
2,2,2,2,2,2,2,2,2,2,2,2,2,2,2,2,2,2,2,2,2
2,2,2,2,2,2,2,2,2,2,2,2,2,2,2,2,2,2,2,2,2
2,2,2,2,2,2,2,2,2,2,2,2,2,2,2,2,2,2,2,2,2
2,2,2,2,2,2,2,2,2,2,2,2,2,2,2,2,2,2,2,2,2
2,2,2,2,2,2,2,2,2,2,2,2,2,2,2,2,2,2,2,2,2
2,2,2,2,2,2,2,2,2,2,2,2,2,2,2,2,2,2,2,2,2
2,2,2,2,2,2,2,2,2,2,2,2,7,7,7,7,7,2,2,2,2
2,2,2,2,2,2,2,2,2,2,2,7,0,0,0,0,7,2,2,2,2
2,2,2,2,2,2,2,7,7,7,7,7,0,0,0,0,7,2,2,2,2
2,2,2,2,2,2,2,11,0,0,0,7,0,0,0,0,7,2,2,2,2
2,2,2,2,7,7,7,7,7,7,7,7,0,0,0,0,7,2,2,2,2
2,2,2,2,2,2,2,2,2,7,9,0,0,0,0,0,7,2,2,2,2
2,2,2,2,2,2,2,2,2,7,0,0,0,0,0,0,7,2,2,2,2
2,2,2,2,2,2,2,2,2,7,0,0,0,0,0,0,7,2,2,2,2
2,2,2,2,2,2,2,2,2,7,0,0,0,0,0,0,7,2,2,2,2
2,2,2,2,2,2,2,2,2,7,7,7,7,7,7,7,7,2,2,2,2
2,2,2,2,2,2,2,2,2,2,2,2,2,2,2,2,2,2,2,2,2
2,2,2,2,2,2,2,2,2,2,2,2,2,2,2,2,2,2,2,2,2
2,2,2,2,2,2,2,2,2,2,2,2,2,2,2,2,2,2,2,2,2
2,2,2,2,2,2,2,2,2,2,2,2,2,2,2,2,2,2,2,2,2
2,2,2,2,2,2,2,2,2,2,2,2,2,2,2,2,2,2,2,2,2
2,2,2,2,2,2,2,2,2,2,2,2,2,2,2,2,2,2,2,2,2
endlayer

layer
2,2,2,2,2,2,2,2,2,2,2,2,2,2,2,2,2,2,2,2,2
2,2,2,2,2,16,16,17,16,16,2,2,2,2,2,2,2,2,2,2,2
2,2,2,2,2,16,16,17,16,16,2,2,2,2,2,2,2,2,2,2,2
2,2,2,2,2,16,16,17,16,16,2,2,2,2,2,2,2,2,2,2,2
2,2,2,2,2,16,16,17,16,16,2,2,2,2,2,2,2,2,2,2,2
2,2,2,2,2,16,16,17,16,16,2,2,2,2,2,2,2,2,2,2,2
2,2,2,2,2,16,16,17,16,16,2,2,2,2,2,2,2,2,2,2,2
2,2,2,2,2,16,16,17,16,16,2,2,2,2,2,2,2,2,2,2,2
2,2,2,2,2,2,2,2,2,2,2,18,18,18,18,18,2,2,2,2,2
2,2,2,2,2,2,21,20,19,19,19,7,18,18,18,18,2,2,2,2,2
2,2,2,2,2,2,11,0,0,0,0,7,18,18,18,18,2,2,2,2,2
2,2,2,2,2,7,7,7,7,7,7,2,18,18,18,18,2,2,2,2,2
2,2,2,2,2,22,22,22,22,22,22,22,22,18,18,18,2,2,2,2,2
2,2,2,2,2,22,22,22,22,22,22,22,22,18,18,18,2,2,2,2,2
2,2,2,2,2,22,22,22,22,22,22,22,22,18,18,18,2,2,2,2,2
2,2,2,2,2,22,22,22,22,22,22,22,22,18,18,18,2,2,2,2,2
2,2,2,2,2,22,22,22,22,22,22,2,2,2,2,2,2,2,2,2,2
2,2,2,2,7,7,7,7,7,7,7,7,2,2,2,2,2,2,2,2,2
23,2,23,23,2,23,23,23,2,23,23,23,23,2,23,2,23,2,2,2,2
2,23,2,23,23,23,2,23,23,2,2,23,23,23,23,23,2,23,2,2,23
23,2,2,2,23,23,23,23,23,23,2,23,2,2,23,23,23,23,2,23,2
2,2,2,2,2,2,2,2,2,2,2,2,2,2,2,2,2,2,2,2,2
2,2,2,2,2,2,2,2,2,2,2,2,2,2,2,2,2,2,2,2,2
endlayer

layer
0,0,0,24,24,24,24,24,24,24,24,24,0,0,0,0,0,0,0,0,0
0,0,0,24,0,25,0,0,26,25,0,24,0,0,0,0,0,0,0,0,0
0,0,0,24,0,0,27,0,26,27,0,24,0,0,0,0,0,0,0,0,0
0,0,0,24,0,26,26,0,27,26,0,24,0,0,0,0,0,0,0,0,0
0,0,0,24,0,26,27,0,25,0,0,24,0,0,0,0,0,0,0,0,0
0,0,0,24,0,26,0,0,27,25,0,24,0,0,0,0,0,0,0,0,0
0,0,0,24,0,27,25,0,25,26,0,24,0,0,0,0,0,0,0,0,0
0,0,0,24,0,27,25,0,0,26,0,28,22,22,22,22,21,0,0,0,0
0,0,0,24,0,0,0,0,0,0,0,0,0,0,0,0,18,0,0,0,0
0,0,0,24,0,0,0,0,0,0,0,18,0,0,29,0,18,0,0,0,0
0,0,0,24,0,0,0,0,0,0,0,18,0,31,29,0,30,0,0,0,0
0,0,0,24,21,7,7,7,7,7,7,32,0,29,0,29,30,0,0,0,0
0,0,0,0,7,36,36,34,35,34,34,33,29,22,29,30,18,0,0,0,0
0,0,0,0,7,0,0,0,0,0,0,0,0,0,0,29,18,0,0,0,0
0,0,0,0,7,0,34,0,34,34,0,37,0,0,0,0,18,0,0,0,0
0,0,0,0,7,0,0,0,0,0,0,37,0,0,0,0,18,0,0,0,0
0,0,0,0,28,0,0,0,0,0,0,21,7,7,7,7,19,0,0,0,0
0,0,0,0,0,0,0,0,0,0,0,0,0,0,0,0,0,0,0,0,0
0,0,0,0,0,0,0,0,0,0,0,0,0,0,0,0,0,0,0,0,0
0,0,0,0,0,0,0,0,0,0,0,0,0,0,0,0,0,0,0,0,0
0,0,0,0,0,0,0,0,0,0,0,0,0,0,0,0,0,0,0,0,0
0,0,0,0,0,0,0,0,0,0,0,0,0,0,0,0,0,0,0,0,0
0,0,0,38,0,0,0,0,0,0,0,0,0,0,0,0,0,0,0,0,0
endlayer

layer
0,0,0,0,0,0,0,0,0,0,0,0,0,0,0,0,0,0,0,0,0
0,0,0,0,0,0,0,0,0,0,0,0,0,0,0,0,0,0,0,0,0
0,0,0,0,0,0,0,0,0,0,0,0,0,0,0,0,0,0,0,0,0
0,0,0,0,0,0,0,0,0,0,0,0,0,0,0,0,0,0,0,0,0
0,0,0,0,0,0,0,0,0,0,0,0,0,0,0,0,0,0,0,0,0
0,0,0,0,0,0,0,0,0,0,0,0,0,0,0,0,0,0,0,0,0
0,0,0,0,0,0,0,0,0,0,0,0,0,0,0,0,0,0,0,0,0
0,0,0,0,0,0,0,0,0,0,0,20,22,22,22,22,21,0,0,0,0
0,0,0,0,0,0,0,0,0,0,0,0,0,0,0,0,22,0,0,0,0
0,0,0,0,0,0,0,0,0,0,0,18,0,0,0,0,0,0,0,0,0
0,0,0,0,0,0,0,0,0,0,0,33,0,0,0,0,0,0,0,0,0
0,0,0,0,21,7,7,35,0,7,7,0,0,0,0,0,0,0,0,0,0
0,0,0,0,7,0,35,0,0,35,0,0,0,0,0,0,30,0,0,0,0
0,0,0,0,0,0,0,0,0,0,0,0,0,0,0,0,0,0,0,0,0
0,0,0,0,0,0,0,0,0,0,0,37,0,0,0,0,0,0,0,0,0
0,0,0,0,7,0,0,0,0,0,0,33,0,0,0,0,18,0,0,0,0
0,0,0,0,21,0,0,0,0,0,0,39,7,0,0,7,21,0,0,0,0
0,0,0,0,0,0,0,0,0,0,0,0,0,0,0,0,0,0,0,0,0
0,0,0,0,0,0,0,0,0,0,0,0,0,0,0,0,0,0,0,0,0
0,0,0,0,0,0,0,0,0,0,0,0,0,0,0,0,0,0,0,0,0
0,0,0,0,0,0,0,0,0,0,0,0,0,0,0,0,0,0,0,0,0
0,0,0,0,0,0,0,0,0,0,0,0,0,0,0,0,0,0,0,0,0
0,0,0,0,0,0,0,0,0,0,0,0,0,0,0,0,0,0,0,0,0
endlayer

layer
0,0,0,0,0,0,0,0,0,0,0,0,0,0,0,0,0,0,0,0,0
0,0,0,0,0,0,0,0,0,0,0,0,0,0,0,0,0,0,0,0,0
0,0,0,0,0,0,0,0,0,0,0,0,0,0,0,0,0,0,0,0,0
0,0,0,0,0,0,0,0,0,0,0,0,0,0,0,0,0,0,0,0,0
0,0,0,0,0,0,0,0,0,0,0,0,0,0,0,0,0,0,0,0,0
0,0,0,0,0,0,0,0,0,0,0,0,0,0,0,0,0,0,0,0,0
0,0,0,0,0,0,0,0,0,0,0,0,0,0,0,0,0,0,0,0,0
0,0,0,0,0,0,0,0,0,0,0,20,31,22,22,22,40,0,0,0,0
0,0,0,0,0,0,0,0,0,0,0,18,0,0,0,0,18,0,0,0,0
0,0,0,0,0,0,0,0,0,0,0,33,0,0,0,0,30,0,0,0,0
0,0,0,0,0,0,0,0,0,0,0,0,0,0,0,0,0,0,0,0,0
0,0,0,0,21,7,0,0,0,35,7,0,0,0,0,0,0,0,0,0,0
0,0,0,0,7,0,0,0,0,0,0,0,0,0,0,0,0,0,0,0,0
0,0,0,0,7,0,0,0,0,0,0,0,0,0,0,0,41,0,0,0,0
0,0,0,0,7,0,0,0,0,0,0,33,0,0,0,0,41,0,0,0,0
0,0,0,0,7,0,0,0,0,0,0,0,0,0,0,0,18,0,0,0,0
0,0,0,0,39,0,0,0,0,0,0,0,7,7,7,7,32,0,0,0,0
0,0,0,0,0,0,0,0,0,0,0,0,0,0,0,0,0,0,0,0,0
0,0,0,0,0,0,0,0,0,0,0,0,0,0,0,0,0,0,0,0,0
0,0,0,0,0,0,0,0,0,0,0,0,0,0,0,0,0,0,0,0,0
0,0,0,0,0,0,0,0,0,0,0,0,0,0,0,0,0,0,0,0,0
0,0,0,0,0,0,0,0,0,0,0,0,0,0,0,0,0,0,0,0,0
0,0,0,0,0,0,0,0,0,0,0,0,0,0,0,0,0,0,0,0,0
endlayer

layer
0,0,0,0,0,0,0,0,0,0,0,0,0,0,0,0,0,0,0,0,0
0,0,0,0,0,0,0,0,0,0,0,0,0,0,0,0,0,0,0,0,0
0,0,0,0,0,0,0,0,0,0,0,0,0,0,0,0,0,0,0,0,0
0,0,0,0,0,0,0,0,0,0,0,0,0,0,0,0,0,0,0,0,0
0,0,0,0,0,0,0,0,0,0,0,0,0,0,0,0,0,0,0,0,0
0,0,0,0,0,0,0,0,0,0,0,0,0,0,0,0,0,0,0,0,0
0,0,0,0,0,0,0,0,0,0,0,0,0,0,0,0,0,0,0,0,0
0,0,0,0,0,0,0,0,0,0,0,29,31,31,31,41,29,0,0,0,0
0,0,0,0,0,0,0,0,0,0,0,29,42,0,0,42,29,0,0,0,0
0,0,0,0,0,0,0,0,0,0,0,29,0,0,0,0,29,0,0,0,0
0,0,0,0,0,0,0,0,0,0,0,0,0,0,0,0,0,0,0,0,0
0,0,0,0,0,0,0,0,0,0,0,0,0,0,0,0,0,0,0,0,0
0,0,0,0,0,0,0,0,0,0,0,0,0,0,0,0,0,0,0,0,0
0,0,0,0,18,0,0,0,0,0,0,33,0,0,0,0,29,0,0,0,0
0,0,0,0,18,0,0,0,0,0,0,43,42,0,0,42,29,0,0,0,0
0,0,0,0,0,0,0,0,0,0,0,0,42,0,0,42,29,0,0,0,0
0,0,0,0,0,0,0,0,0,0,0,0,41,22,22,22,29,0,0,0,0
0,0,0,0,0,0,0,0,0,0,0,0,0,0,0,0,0,0,0,0,0
0,0,0,0,0,0,0,0,0,0,0,0,0,0,0,0,0,0,0,0,0
0,0,0,0,0,0,0,0,0,0,0,0,0,0,0,0,0,0,0,0,0
0,0,0,0,0,0,0,0,0,0,0,0,0,0,0,0,0,0,0,0,0
0,0,0,0,0,0,0,0,0,0,0,0,0,0,0,0,0,0,0,0,0
0,0,0,0,0,0,0,0,0,0,0,0,0,0,0,0,0,0,0,0,0
endlayer

layer
0,0,0,0,0,0,0,0,0,0,0,0,0,0,0,0,0,0,0,0,0
0,0,0,0,0,0,0,0,0,0,0,0,0,0,0,0,0,0,0,0,0
0,0,0,0,0,0,0,0,0,0,0,0,0,0,0,0,0,0,0,0,0
0,0,0,0,0,0,0,0,0,0,0,0,0,0,0,0,0,0,0,0,0
0,0,0,0,0,0,0,0,0,0,0,0,0,0,0,0,0,0,0,0,0
0,0,0,0,0,0,0,0,0,0,0,0,0,0,0,0,0,0,0,0,0
0,0,0,0,0,0,0,0,0,0,0,0,0,0,0,0,0,0,0,0,0
0,0,0,0,0,0,0,0,0,0,0,0,0,29,29,0,0,0,0,0,0
0,0,0,0,0,0,0,0,0,0,0,0,0,0,29,0,0,0,0,0,0
0,0,0,0,0,0,0,0,0,0,0,0,0,0,0,0,0,0,0,0,0
0,0,0,0,0,0,0,0,0,0,0,0,0,0,0,0,0,0,0,0,0
0,0,0,0,0,0,0,0,0,0,0,0,0,0,0,0,0,0,0,0,0
0,0,0,0,0,0,0,0,0,0,0,0,0,0,0,0,0,0,0,0,0
0,0,0,0,0,0,0,0,0,0,0,0,0,0,0,0,0,0,0,0,0
0,0,0,0,0,0,0,0,0,0,0,0,0,0,0,0,0,0,0,0,0
0,0,0,0,0,0,0,0,0,0,0,0,0,29,29,0,0,0,0,0,0
0,0,0,0,0,0,0,0,0,0,0,0,0,29,29,0,0,0,0,0,0
0,0,0,0,0,0,0,0,0,0,0,0,0,0,0,0,0,0,0,0,0
0,0,0,0,0,0,0,0,0,0,0,0,0,0,0,0,0,0,0,0,0
0,0,0,0,0,0,0,0,0,0,0,0,0,0,0,0,0,0,0,0,0
0,0,0,0,0,0,0,0,0,0,0,0,0,0,0,0,0,0,0,0,0
0,0,0,0,0,0,0,0,0,0,0,0,0,0,0,0,0,0,0,0,0
0,0,0,0,0,0,0,0,0,0,0,0,0,0,0,0,0,0,0,0,0
endlayer

